<?xml version="1.0" encoding="utf-8"?>
<!-- This URDF was automatically created by SolidWorks to URDF Exporter! Originally created by Stephen Brawner (brawner@gmail.com) 
     Commit Version: 1.6.0-4-g7f85cfe  Build Version: 1.6.7995.38578
     For more information, please see http://wiki.ros.org/sw_urdf_exporter -->
<robot name="car2">
  <link name="car">
    <inertial>
      <origin xyz="-0.0027074 -3.0003E-16 0.017167" rpy="0 0 0" />
      <mass value="0.02" />
      <inertia ixx="0.00043157" ixy="-4.1737E-18" ixz="2.7447E-06" iyy="0.0012682" iyz="3.0153E-20" izz="0.0016932" />
    </inertial>
    <visual>
      <origin xyz="0 0 0" rpy="0 0 0" />
      <geometry>
        <mesh filename="package://car2/meshes/car.STL" />
      </geometry>
      <material name="">
        <color rgba="0.79216 0.81961 0.93333 1" />
      </material>
    </visual>
    <collision>
      <origin xyz="0 0 0" rpy="0 0 0" />
      <geometry>
        <mesh filename="package://car2/meshes/car.STL" />
      </geometry>
    </collision>
  </link>
  <link name="r_wheel_link">
    <inertial>
      <origin xyz="-0.00378190594294554 1.97642154184385E-07 -0.00657870584365291" rpy="0 0 0" />
      <mass value="0.00124397619652833" />
      <inertia ixx="3.35972126452314E-08" ixy="-1.24282669053489E-12" ixz="7.42692787875443E-09" iyy="8.89962659917208E-08" iyz="-1.41962818240552E-12" izz="7.26260074714814E-08" />
    </inertial>
    <visual>
      <origin xyz="0 0 0" rpy="0 0 0" />
      <geometry>
        <mesh filename="package://car2/meshes/r_wheel_link.STL" />
      </geometry>
      <material name="">
        <color rgba="0.792156862745098 0.819607843137255 0.933333333333333 1" />
      </material>
    </visual>
    <collision>
      <origin xyz="0 0 0" rpy="0 0 0" />
      <geometry>
        <mesh filename="package://car2/meshes/r_wheel_link.STL" />
      </geometry>
    </collision>
  </link>
  <joint name="r_wheel_joint" type="revolute">
    <origin xyz="0.076709 -0.050979 0.012" rpy="0 0 0" />
    <parent link="car" />
    <child link="r_wheel_link" />
    <axis xyz="0 0 1" />
    <limit lower="0" upper="0" effort="0" velocity="0" />
  </joint>
  <link name="wheel1_link">
    <inertial>
      <origin xyz="-1.38777878078145E-17 0.00835500060925576 -5.20417042793042E-17" rpy="0 0 0" />
      <mass value="0.05" />
      <inertia ixx="2.97355567460469E-06" ixy="-6.48236144271607E-21" ixz="-4.61169347369653E-21" iyy="4.93022491701447E-06" iyz="9.14430351930179E-22" izz="2.97355567460471E-06" />
    </inertial>
    <visual>
      <origin xyz="0 0 0" rpy="0 0 0" />
      <geometry>
        <mesh filename="package://car2/meshes/wheel1_link.STL" />
      </geometry>
      <material name="">
        <color rgba="0.792156862745098 0.819607843137255 0.933333333333333 1" />
      </material>
    </visual>
    <collision>
      <origin xyz="0 0 0" rpy="0 0 0" />
      <geometry>
        <mesh filename="package://car2/meshes/wheel1_link.STL" />
      </geometry>
    </collision>
  </link>
  <joint name="wheel1_joint" type="continuous">
    <origin xyz="0 -0.025 -0.005" rpy="0 0 0" />
    <parent link="r_wheel_link" />
    <child link="wheel1_link" />
    <axis xyz="0 1 0" />
  </joint>
  <link name="l_wheel_link">
    <inertial>
      <origin xyz="-0.00378190594294553 1.97642154142752E-07 -0.00657870584365291" rpy="0 0 0" />
      <mass value="0.00124397619652833" />
      <inertia ixx="3.35972126452314E-08" ixy="-1.24282669034389E-12" ixz="7.42692787875444E-09" iyy="8.89962659917207E-08" iyz="-1.41962818244858E-12" izz="7.26260074714813E-08" />
    </inertial>
    <visual>
      <origin xyz="0 0 0" rpy="0 0 0" />
      <geometry>
        <mesh filename="package://car2/meshes/l_wheel_link.STL" />
      </geometry>
      <material name="">
        <color rgba="0.792156862745098 0.819607843137255 0.933333333333333 1" />
      </material>
    </visual>
    <collision>
      <origin xyz="0 0 0" rpy="0 0 0" />
      <geometry>
        <mesh filename="package://car2/meshes/l_wheel_link.STL" />
      </geometry>
    </collision>
  </link>
  <joint name="l_wheel_joint" type="revolute">
    <origin xyz="0.076709 0.050979 0.012" rpy="0 0 0" />
    <parent link="car" />
    <child link="l_wheel_link" />
    <axis xyz="0 0 1" />
    <limit lower="0" upper="0" effort="0" velocity="0" />
  </joint>
  <link name="wheel2_link">
    <inertial>
      <origin xyz="-3.19189119579733E-16 -0.00835500060925579 2.46330733588707E-16" rpy="0 0 0" />
      <mass value="0.05" />
      <inertia ixx="2.97355567460469E-06" ixy="5.43807803572984E-20" ixz="7.62557127197317E-21" iyy="4.93022491701446E-06" iyz="3.52125469475346E-21" izz="2.9735556746047E-06" />
    </inertial>
    <visual>
      <origin xyz="0 0 0" rpy="0 0 0" />
      <geometry>
        <mesh filename="package://car2/meshes/wheel2_link.STL" />
      </geometry>
      <material name="">
        <color rgba="0.792156862745098 0.819607843137255 0.933333333333333 1" />
      </material>
    </visual>
    <collision>
      <origin xyz="0 0 0" rpy="0 0 0" />
      <geometry>
        <mesh filename="package://car2/meshes/wheel2_link.STL" />
      </geometry>
    </collision>
  </link>
  <joint name="wheel2_joint" type="continuous">
    <origin xyz="0 0.025 -0.005" rpy="0 0 0" />
    <parent link="l_wheel_link" />
    <child link="wheel2_link" />
    <axis xyz="0 1 0" />
  </joint>
  <link name="wheel3_link">
    <inertial>
      <origin xyz="-2.08166817117217E-16 -0.00835500060925574 -6.76542155630955E-17" rpy="0 0 0" />
      <mass value="0.05" />
      <inertia ixx="2.9735556746047E-06" ixy="5.55201970900145E-20" ixz="4.71105208243082E-21" iyy="4.93022491701447E-06" iyz="-2.30328909794717E-21" izz="2.9735556746047E-06" />
    </inertial>
    <visual>
      <origin xyz="0 0 0" rpy="0 0 0" />
      <geometry>
        <mesh filename="package://car2/meshes/wheel3_link.STL" />
      </geometry>
      <material name="">
        <color rgba="0.792156862745098 0.819607843137255 0.933333333333333 1" />
      </material>
    </visual>
    <collision>
      <origin xyz="0 0 0" rpy="0 0 0" />
      <geometry>
        <mesh filename="package://car2/meshes/wheel3_link.STL" />
      </geometry>
    </collision>
  </link>
  <joint name="wheel3_joint" type="continuous">
    <origin xyz="-0.078291 0.076 0.007" rpy="0 0 0" />
    <parent link="car" />
    <child link="wheel3_link" />
    <axis xyz="0 1 0" />
  </joint>
  <link name="wheel4_link">
    <inertial>
      <origin xyz="8.32667268468867E-17 0.00835500060925574 1.50920942409982E-16" rpy="0 0 0" />
      <mass value="0.05" />
      <inertia ixx="2.9735556746047E-06" ixy="-9.71262221525064E-21" ixz="-6.50758497531929E-21" iyy="4.93022491701447E-06" iyz="-6.39439453700751E-21" izz="2.9735556746047E-06" />
    </inertial>
    <visual>
      <origin xyz="0 0 0" rpy="0 0 0" />
      <geometry>
        <mesh filename="package://car2/meshes/wheel4_link.STL" />
      </geometry>
      <material name="">
        <color rgba="0.792156862745098 0.819607843137255 0.933333333333333 1" />
      </material>
    </visual>
    <collision>
      <origin xyz="0 0 0" rpy="0 0 0" />
      <geometry>
        <mesh filename="package://car2/meshes/wheel4_link.STL" />
      </geometry>
    </collision>
  </link>
  <joint name="wheel4_joint" type="continuous">
    <origin xyz="-0.078291 -0.076 0.007" rpy="0 0 0" />
    <parent link="car" />
    <child link="wheel4_link" />
    <axis xyz="0 1 0" />
  </joint>
  <link name="arm_base_link">
    <inertial>
      <origin xyz="0.000910433121614637 -0.00433390442586054 8.32773883386243E-09" rpy="0 0 0" />
      <mass value="0.07017488534617" />
      <inertia ixx="4.38116101053683E-05" ixy="2.35120127682087E-06" ixz="-1.5358404688431E-11" iyy="3.10677926351619E-05" iyz="5.45464427696522E-12" izz="3.06109146907153E-05" />
    </inertial>
    <visual>
      <origin xyz="0 0 0" rpy="0 0 0" />
      <geometry>
        <mesh filename="package://car2/meshes/arm_base_link.STL" />
      </geometry>
      <material name="">
        <color rgba="0.792156862745098 0.819607843137255 0.933333333333333 1" />
      </material>
    </visual>
    <collision>
      <origin xyz="0 0 0" rpy="0 0 0" />
      <geometry>
        <mesh filename="package://car2/meshes/arm_base_link.STL" />
      </geometry>
    </collision>
  </link>
  <joint name="arm_base_joint" type="revolute">
    <origin xyz="-0.00079055 0.0018928 0.048" rpy="3.1416 -1.5708 0" />
    <parent link="car" />
    <child link="arm_base_link" />
    <axis xyz="1 0 0" />
    <limit lower="-3.14" upper="3.14" effort="10" velocity="1" />
  </joint>
  <link name="arm_link">
    <inertial>
      <origin xyz="0.0422431195151998 0.00482877870291687 -1.11860933016406E-09" rpy="0 0 0" />
      <mass value="0.025111069557619" />
      <inertia ixx="1.50238726311773E-06" ixy="-1.95293714809877E-07" ixz="-1.09917391696648E-12" iyy="2.24829187572783E-05" iyz="4.78031926159686E-14" izz="2.14299431344385E-05" />
    </inertial>
    <visual>
      <origin xyz="0 0 0" rpy="0 0 0" />
      <geometry>
        <mesh filename="package://car2/meshes/arm_link.STL" />
      </geometry>
      <material name="">
        <color rgba="0.792156862745098 0.819607843137255 0.933333333333333 1" />
      </material>
    </visual>
    <collision>
      <origin xyz="0 0 0" rpy="0 0 0" />
      <geometry>
        <mesh filename="package://car2/meshes/arm_link.STL" />
      </geometry>
    </collision>
  </link>
  <joint name="arm_joint" type="revolute">
    <origin xyz="0.02457 -0.0018928 0" rpy="0 1.5708 0" />
    <parent link="arm_base_link" />
    <child link="arm_link" />
    <axis xyz="0 1 0" />
    <limit lower="-3.14" upper="0" effort="10" velocity="1" />
  </joint>
  <link name="camera">
    <inertial>
      <origin xyz="-0.00892618611124281 2.09105677235725E-18 -0.000789549115426313" rpy="0 0 0" />
      <mass value="0.00366758846903219" />
      <inertia ixx="1.48146950827686E-07" ixy="-2.10640073960399E-23" ixz="1.08383834631344E-08" iyy="1.59703995617956E-07" iyz="-4.26232491798236E-24" izz="1.38552825545768E-07" />
    </inertial>
    <visual>
      <origin xyz="0 0 0" rpy="0 0 0" />
      <geometry>
        <mesh filename="package://car2/meshes/camera.STL" />
      </geometry>
      <material name="">
        <color rgba="0.792156862745098 0.819607843137255 0.933333333333333 1" />
      </material>
    </visual>
    <collision>
      <origin xyz="0 0 0" rpy="0 0 0" />
      <geometry>
        <mesh filename="package://car2/meshes/camera.STL" />
      </geometry>
    </collision>
  </link>
  <joint name="camera_joint" type="fixed">
    <origin xyz="0.12621 0 0.0075" rpy="0 0 0" />
    <parent link="car" />
    <child link="camera" />
    <axis xyz="0 0 0" />
  </joint>
  <link name="IMU">
    <inertial>
      <origin xyz="8.67361737988404E-19 0 -0.0025" rpy="0 0 0" />
      <mass value="0.001" />
      <inertia ixx="3.54166666666667E-08" ixy="-7.04288268018996E-22" ixz="1.08420217248529E-25" iyy="1.04166666666667E-08" iyz="-7.82164340710411E-25" izz="4.16666666666667E-08" />
    </inertial>
    <visual>
      <origin xyz="0 0 0" rpy="0 0 0" />
      <geometry>
        <mesh filename="package://car2/meshes/IMU.STL" />
      </geometry>
      <material name="">
        <color rgba="0.792156862745098 0.819607843137255 0.933333333333333 1" />
      </material>
    </visual>
    <collision>
      <origin xyz="0 0 0" rpy="0 0 0" />
      <geometry>
        <mesh filename="package://car2/meshes/IMU.STL" />
      </geometry>
    </collision>
  </link>
  <joint name="IMU_joint" type="fixed">
    <origin xyz="0.0042095 0.0025 0.005" rpy="0 0 0" />
    <parent link="car" />
    <child link="IMU" />
    <axis xyz="0 0 0" />
  </joint>
 
  <gazebo reference="IMU">
      <sensor name="imu_sensor" type="imu">
          <always_on>true</always_on>
          <update_rate>100</update_rate>
          <visualize>true</visualize>
          <plugin filename="libgazebo_ros_imu_sensor.so" name="imu_plugin">
              <topicName>/imu/data</topicName>
              <bodyName>IMU</bodyName>   <!-- Đảm bảo bodyName trùng với imu_link -->
              <updateRateHZ>100.0</updateRateHZ>
              <gaussianNoise>0.01</gaussianNoise>
              <xyzOffset>0 0 0</xyzOffset>
              <rpyOffset>0 0 0</rpyOffset>
              <frameName>IMU</frameName>
              <initialOrientationAsReference>false</initialOrientationAsReference>
          </plugin>
      </sensor>
  </gazebo>

  <gazebo>
    <plugin name="arm_trajectory_controller" filename="libgazebo_ros_joint_pose_trajectory.so">
      <robotNamespace>/car2</robotNamespace>
      <topicName>/car2/arm_trajectory_command</topicName>
      <joints>
        <joint>arm_base_joint</joint>
        <joint>arm_joint</joint>
      </joints>
      <updateRate>100</updateRate>
    </plugin>
  </gazebo>
  
  <gazebo reference="camera">
      <sensor type="camera" name="camera_sensor">
          <update_rate>30</update_rate>
          <camera>
              <horizontal_fov>1.57</horizontal_fov>
              <image>
                  <width>640</width>
                  <height>480</height>
                  <format>R8G8B8</format>
              </image>
              <clip>
                  <near>0.1</near>
                  <far>100</far>
              </clip>
          </camera>
          <plugin name="camera_plugin" filename="libgazebo_ros_camera.so">
              <alwaysOn>true</alwaysOn>
              <updateRate>30.0</updateRate>
              <cameraName>robot_camera</cameraName>
              <imageTopicName>/camera/image_raw</imageTopicName>
              <cameraInfoTopicName>/camera/camera_info</cameraInfoTopicName>
              <frameName>camera</frameName>
          </plugin>
      </sensor>
  </gazebo>

  <gazebo>
   <plugin name="skid_steer_plugin" filename="libgazebo_ros_skid_steer_drive.so">
   
       <!-- Khớp nối của bánh xe -->
       <leftFrontJoint>wheel2_joint</leftFrontJoint>  <!-- Trái trước -->
       <rightFrontJoint>wheel1_joint</rightFrontJoint> <!-- Phải trước -->
       <leftRearJoint>wheel3_joint</leftRearJoint>  <!-- Trái sau -->
       <rightRearJoint>wheel4_joint</rightRearJoint> <!-- Phải sau -->


       <!-- Thông số điều khiển -->
       <wheelSeparation>0.3</wheelSeparation>
       <wheelDiameter>0.1</wheelDiameter>
       <torque>10.0</torque>


       <!-- Cấu hình ROS -->
       <updateRate>100.0</updateRate>
       <commandTopic>cmd_vel</commandTopic>
       <odometrySource>encoder</odometrySource>
       <odometryTopic>odom</odometryTopic>
       <odometryFrame>odom</odometryFrame>
       <robotBaseFrame>base_link</robotBaseFrame>


       <!-- Thông số biến đổi quán tính -->
       <covariance_x>0.0001</covariance_x>
       <covariance_y>0.0001</covariance_y>
       <covariance_yaw>0.01</covariance_yaw>
   </plugin>
 </gazebo>

</robot>